log/output_50_2022_CNN_gpu0.log
wandb: Currently logged in as: pqy000 (pqythu). Use `wandb login --relogin` to force relogin
GPU device ID: 0
newdata/50_2022.npy
0
2024-09-07 12:09:26.508665: I tensorflow/core/platform/cpu_feature_guard.cc:193] This TensorFlow binary is optimized with oneAPI Deep Neural Network Library (oneDNN) to use the following CPU instructions in performance-critical operations:  AVX2 FMA
To enable them in other operations, rebuild TensorFlow with the appropriate compiler flags.
2024-09-07 12:09:27.395916: W tensorflow/compiler/xla/stream_executor/platform/default/dso_loader.cc:64] Could not load dynamic library 'libnvinfer.so.7'; dlerror: libnvinfer.so.7: cannot open shared object file: No such file or directory; LD_LIBRARY_PATH: /opt/cudnn/lib64:/usr/local/cuda/lib64
2024-09-07 12:09:27.396018: W tensorflow/compiler/xla/stream_executor/platform/default/dso_loader.cc:64] Could not load dynamic library 'libnvinfer_plugin.so.7'; dlerror: libnvinfer_plugin.so.7: cannot open shared object file: No such file or directory; LD_LIBRARY_PATH: /opt/cudnn/lib64:/usr/local/cuda/lib64
2024-09-07 12:09:27.396031: W tensorflow/compiler/tf2tensorrt/utils/py_utils.cc:38] TF-TRT Warning: Cannot dlopen some TensorRT libraries. If you would like to use Nvidia GPU with TensorRT, please make sure the missing libraries mentioned above are installed properly.
wandb: wandb version 0.17.9 is available!  To upgrade, please run:
wandb:  $ pip install wandb --upgrade
wandb: Tracking run with wandb version 0.12.17
wandb: Run data is saved locally in /home/qingyi/GPU20/DeepLOB/wandb/run-20240907_120919-3a8pr24r
wandb: Run `wandb offline` to turn off syncing.
wandb: Syncing run CNN
wandb: ⭐️ View project at https://wandb.ai/pqythu/futures50
wandb: 🚀 View run at https://wandb.ai/pqythu/futures50/runs/3a8pr24r
Model(
  (conv1): Conv1d(10, 64, kernel_size=(3,), stride=(1,), padding=(1,))
  (conv2): Conv1d(64, 64, kernel_size=(3,), stride=(1,), padding=(1,))
  (pool): MaxPool1d(kernel_size=2, stride=2, padding=0, dilation=1, ceil_mode=False)
  (fc): Linear(in_features=512, out_features=5, bias=True)
)
number of parameters: 16901
Training start
epoch  1 | time used:  1.91s | train_loss 1.440 | valid loss 1.380 | valid acc 0.440 | mae 1.913 | mse 7.053 | rmse 2.66 | r2 -1.08 | sharp 1.22
epoch  2 | time used:  0.08s | train_loss 1.509 | valid loss 1.510 | valid acc 0.393 | mae 2.087 | mse 7.753 | rmse 2.78 | r2 -1.28 | sharp 0.00
epoch  3 | time used:  0.07s | train_loss 1.573 | valid loss 1.510 | valid acc 0.393 | mae 2.087 | mse 7.753 | rmse 2.78 | r2 -1.28 | sharp 0.00
epoch  4 | time used:  0.08s | train_loss 1.568 | valid loss 1.510 | valid acc 0.393 | mae 2.087 | mse 7.753 | rmse 2.78 | r2 -1.28 | sharp 0.00
epoch  5 | time used:  0.09s | train_loss 1.569 | valid loss 1.510 | valid acc 0.393 | mae 2.087 | mse 7.753 | rmse 2.78 | r2 -1.28 | sharp 0.00
epoch  6 | time used:  0.09s | train_loss 1.560 | valid loss 1.510 | valid acc 0.393 | mae 2.087 | mse 7.753 | rmse 2.78 | r2 -1.28 | sharp 0.00
epoch  7 | time used:  0.07s | train_loss 1.571 | valid loss 1.510 | valid acc 0.393 | mae 2.087 | mse 7.753 | rmse 2.78 | r2 -1.28 | sharp 0.00
epoch  8 | time used:  0.07s | train_loss 1.568 | valid loss 1.510 | valid acc 0.393 | mae 2.087 | mse 7.753 | rmse 2.78 | r2 -1.28 | sharp 0.00
epoch  9 | time used:  0.09s | train_loss 1.573 | valid loss 1.510 | valid acc 0.393 | mae 2.087 | mse 7.753 | rmse 2.78 | r2 -1.28 | sharp 0.00
epoch 10 | time used:  0.07s | train_loss 1.568 | valid loss 1.510 | valid acc 0.393 | mae 2.087 | mse 7.753 | rmse 2.78 | r2 -1.28 | sharp 0.00
saving the model to ./save/2022_50/CNN/checkpoint10.pt
epoch 11 | time used:  0.09s | train_loss 1.569 | valid loss 1.510 | valid acc 0.393 | mae 2.087 | mse 7.753 | rmse 2.78 | r2 -1.28 | sharp 0.00
epoch 12 | time used:  0.08s | train_loss 1.570 | valid loss 1.510 | valid acc 0.393 | mae 2.087 | mse 7.753 | rmse 2.78 | r2 -1.28 | sharp 0.00
epoch 13 | time used:  0.08s | train_loss 1.574 | valid loss 1.510 | valid acc 0.393 | mae 2.087 | mse 7.753 | rmse 2.78 | r2 -1.28 | sharp 0.00
epoch 14 | time used:  0.12s | train_loss 1.573 | valid loss 1.510 | valid acc 0.393 | mae 2.087 | mse 7.753 | rmse 2.78 | r2 -1.28 | sharp 0.00
epoch 15 | time used:  0.07s | train_loss 1.569 | valid loss 1.510 | valid acc 0.393 | mae 2.087 | mse 7.753 | rmse 2.78 | r2 -1.28 | sharp 0.00
epoch 16 | time used:  0.06s | train_loss 1.570 | valid loss 1.510 | valid acc 0.393 | mae 2.087 | mse 7.753 | rmse 2.78 | r2 -1.28 | sharp 0.00
epoch 17 | time used:  0.06s | train_loss 1.568 | valid loss 1.510 | valid acc 0.393 | mae 2.087 | mse 7.753 | rmse 2.78 | r2 -1.28 | sharp 0.00
epoch 18 | time used:  0.06s | train_loss 1.572 | valid loss 1.510 | valid acc 0.393 | mae 2.087 | mse 7.753 | rmse 2.78 | r2 -1.28 | sharp 0.00
epoch 19 | time used:  0.06s | train_loss 1.579 | valid loss 1.529 | valid acc 0.393 | mae 2.087 | mse 7.753 | rmse 2.78 | r2 -1.28 | sharp 0.00
epoch 20 | time used:  0.06s | train_loss 1.587 | valid loss 1.883 | valid acc 0.033 | mae 1.792 | mse 4.228 | rmse 2.06 | r2 -0.25 | sharp 1.22
saving the model to ./save/2022_50/CNN/checkpoint20.pt
epoch 21 | time used:  0.06s | train_loss 1.833 | valid loss 1.883 | valid acc 0.033 | mae 1.792 | mse 4.228 | rmse 2.06 | r2 -0.25 | sharp 1.22
epoch 22 | time used:  0.06s | train_loss 1.580 | valid loss 1.380 | valid acc 0.440 | mae 1.913 | mse 7.053 | rmse 2.66 | r2 -1.08 | sharp 1.22
epoch 23 | time used:  0.06s | train_loss 1.425 | valid loss 1.380 | valid acc 0.440 | mae 1.913 | mse 7.053 | rmse 2.66 | r2 -1.08 | sharp 1.22
epoch 24 | time used:  0.06s | train_loss 1.421 | valid loss 1.380 | valid acc 0.440 | mae 1.913 | mse 7.053 | rmse 2.66 | r2 -1.08 | sharp 1.22
epoch 25 | time used:  0.07s | train_loss 1.440 | valid loss 1.510 | valid acc 0.393 | mae 2.087 | mse 7.753 | rmse 2.78 | r2 -1.28 | sharp 0.00
epoch 26 | time used:  0.07s | train_loss 1.453 | valid loss 1.380 | valid acc 0.440 | mae 1.913 | mse 7.053 | rmse 2.66 | r2 -1.08 | sharp 1.22
epoch 27 | time used:  0.07s | train_loss 1.420 | valid loss 1.380 | valid acc 0.440 | mae 1.913 | mse 7.053 | rmse 2.66 | r2 -1.08 | sharp 1.22
epoch 28 | time used:  0.07s | train_loss 1.423 | valid loss 1.380 | valid acc 0.440 | mae 1.913 | mse 7.053 | rmse 2.66 | r2 -1.08 | sharp 1.22
epoch 29 | time used:  0.07s | train_loss 1.427 | valid loss 1.380 | valid acc 0.440 | mae 1.913 | mse 7.053 | rmse 2.66 | r2 -1.08 | sharp 1.22
epoch 30 | time used:  0.07s | train_loss 1.424 | valid loss 1.380 | valid acc 0.440 | mae 1.913 | mse 7.053 | rmse 2.66 | r2 -1.08 | sharp 1.22
saving the model to ./save/2022_50/CNN/checkpoint30.pt
epoch 31 | time used:  0.08s | train_loss 1.424 | valid loss 1.380 | valid acc 0.440 | mae 1.913 | mse 7.053 | rmse 2.66 | r2 -1.08 | sharp 1.22
epoch 32 | time used:  0.08s | train_loss 1.430 | valid loss 1.380 | valid acc 0.440 | mae 1.913 | mse 7.053 | rmse 2.66 | r2 -1.08 | sharp 1.22
epoch 33 | time used:  0.10s | train_loss 1.420 | valid loss 1.380 | valid acc 0.440 | mae 1.913 | mse 7.053 | rmse 2.66 | r2 -1.08 | sharp 1.22
epoch 34 | time used:  0.09s | train_loss 1.423 | valid loss 1.380 | valid acc 0.440 | mae 1.913 | mse 7.053 | rmse 2.66 | r2 -1.08 | sharp 1.22
epoch 35 | time used:  0.10s | train_loss 1.418 | valid loss 1.380 | valid acc 0.440 | mae 1.913 | mse 7.053 | rmse 2.66 | r2 -1.08 | sharp 1.22
epoch 36 | time used:  0.08s | train_loss 1.425 | valid loss 1.380 | valid acc 0.440 | mae 1.913 | mse 7.053 | rmse 2.66 | r2 -1.08 | sharp 1.22
epoch 37 | time used:  0.07s | train_loss 1.423 | valid loss 1.380 | valid acc 0.440 | mae 1.913 | mse 7.053 | rmse 2.66 | r2 -1.08 | sharp 1.22
epoch 38 | time used:  0.08s | train_loss 1.423 | valid loss 1.380 | valid acc 0.440 | mae 1.913 | mse 7.053 | rmse 2.66 | r2 -1.08 | sharp 1.22
epoch 39 | time used:  0.08s | train_loss 1.426 | valid loss 1.380 | valid acc 0.440 | mae 1.913 | mse 7.053 | rmse 2.66 | r2 -1.08 | sharp 1.22
