log/output_50_2022_CNN_gpu4.log
wandb: W&B API key is configured. Use `wandb login --relogin` to force relogin
GPU device ID: 4
newdata/50_2022.npy
0
wandb: wandb version 0.17.9 is available!  To upgrade, please run:
wandb:  $ pip install wandb --upgrade
wandb: Tracking run with wandb version 0.12.17
wandb: Run data is saved locally in /home/qingyi/GPU20/DeepLOB/wandb/run-20240907_160535-127m3htr
wandb: Run `wandb offline` to turn off syncing.
wandb: Syncing run CNN
wandb: ⭐️ View project at https://wandb.ai/pqythu/futures50
wandb: 🚀 View run at https://wandb.ai/pqythu/futures50/runs/127m3htr
2024-09-07 16:05:46.579164: I tensorflow/core/platform/cpu_feature_guard.cc:193] This TensorFlow binary is optimized with oneAPI Deep Neural Network Library (oneDNN) to use the following CPU instructions in performance-critical operations:  AVX2 FMA
To enable them in other operations, rebuild TensorFlow with the appropriate compiler flags.
Model(
  (conv1): Conv1d(10, 64, kernel_size=(3,), stride=(1,), padding=(1,))
  (conv2): Conv1d(64, 64, kernel_size=(3,), stride=(1,), padding=(1,))
  (pool): MaxPool1d(kernel_size=2, stride=2, padding=0, dilation=1, ceil_mode=False)
  (fc): Linear(in_features=512, out_features=5, bias=True)
)
number of parameters: 16901
Training start
epoch  1 | time used:  2.42s | train_loss 1.465 | valid loss 1.555 | valid acc 0.320 | mae 2.115 | mse 7.365 | rmse 2.71 | r2 -1.55 | sharp 0.00
epoch  2 | time used:  0.04s | train_loss 1.482 | valid loss 1.475 | valid acc 0.365 | mae 1.885 | mse 6.445 | rmse 2.54 | r2 -1.23 | sharp 1.02
epoch  3 | time used:  0.04s | train_loss 1.552 | valid loss 1.475 | valid acc 0.365 | mae 1.885 | mse 6.445 | rmse 2.54 | r2 -1.23 | sharp 1.02
epoch  4 | time used:  0.04s | train_loss 1.570 | valid loss 1.475 | valid acc 0.365 | mae 1.885 | mse 6.445 | rmse 2.54 | r2 -1.23 | sharp 1.02
epoch  5 | time used:  0.04s | train_loss 1.573 | valid loss 1.476 | valid acc 0.365 | mae 1.885 | mse 6.445 | rmse 2.54 | r2 -1.23 | sharp 1.02
epoch  6 | time used:  0.06s | train_loss 1.559 | valid loss 1.475 | valid acc 0.365 | mae 1.885 | mse 6.445 | rmse 2.54 | r2 -1.23 | sharp 1.02
epoch  7 | time used:  0.04s | train_loss 1.466 | valid loss 1.555 | valid acc 0.320 | mae 2.115 | mse 7.365 | rmse 2.71 | r2 -1.55 | sharp 0.00
epoch  8 | time used:  0.05s | train_loss 1.493 | valid loss 1.555 | valid acc 0.320 | mae 2.115 | mse 7.365 | rmse 2.71 | r2 -1.55 | sharp 0.00
epoch  9 | time used:  0.06s | train_loss 1.456 | valid loss 1.555 | valid acc 0.320 | mae 2.115 | mse 7.365 | rmse 2.71 | r2 -1.55 | sharp 0.00
epoch 10 | time used:  0.05s | train_loss 1.492 | valid loss 1.555 | valid acc 0.320 | mae 2.115 | mse 7.365 | rmse 2.71 | r2 -1.55 | sharp 0.00
saving the model to ./save/2022_50/CNN/checkpoint10.pt
epoch 11 | time used:  0.05s | train_loss 1.478 | valid loss 1.555 | valid acc 0.320 | mae 2.115 | mse 7.365 | rmse 2.71 | r2 -1.55 | sharp 0.00
epoch 12 | time used:  0.05s | train_loss 1.467 | valid loss 1.555 | valid acc 0.320 | mae 2.115 | mse 7.365 | rmse 2.71 | r2 -1.55 | sharp 0.00
epoch 13 | time used:  0.05s | train_loss 1.477 | valid loss 1.555 | valid acc 0.320 | mae 2.115 | mse 7.365 | rmse 2.71 | r2 -1.55 | sharp 0.00
epoch 14 | time used:  0.04s | train_loss 1.480 | valid loss 1.555 | valid acc 0.320 | mae 2.115 | mse 7.365 | rmse 2.71 | r2 -1.55 | sharp 0.00
epoch 15 | time used:  0.04s | train_loss 1.463 | valid loss 1.555 | valid acc 0.320 | mae 2.115 | mse 7.365 | rmse 2.71 | r2 -1.55 | sharp 0.00
epoch 16 | time used:  0.04s | train_loss 1.458 | valid loss 1.555 | valid acc 0.320 | mae 2.115 | mse 7.365 | rmse 2.71 | r2 -1.55 | sharp 0.00
epoch 17 | time used:  0.05s | train_loss 1.474 | valid loss 1.555 | valid acc 0.320 | mae 2.115 | mse 7.365 | rmse 2.71 | r2 -1.55 | sharp 0.00
epoch 18 | time used:  0.04s | train_loss 1.490 | valid loss 1.555 | valid acc 0.320 | mae 2.115 | mse 7.365 | rmse 2.71 | r2 -1.55 | sharp 0.00
epoch 19 | time used:  0.04s | train_loss 1.477 | valid loss 1.555 | valid acc 0.320 | mae 2.115 | mse 7.365 | rmse 2.71 | r2 -1.55 | sharp 0.00
epoch 20 | time used:  0.04s | train_loss 1.438 | valid loss 1.555 | valid acc 0.320 | mae 2.115 | mse 7.365 | rmse 2.71 | r2 -1.55 | sharp 0.00
saving the model to ./save/2022_50/CNN/checkpoint20.pt
epoch 21 | time used:  0.04s | train_loss 1.477 | valid loss 1.555 | valid acc 0.320 | mae 2.115 | mse 7.365 | rmse 2.71 | r2 -1.55 | sharp 0.00
epoch 22 | time used:  0.04s | train_loss 1.440 | valid loss 1.555 | valid acc 0.320 | mae 2.115 | mse 7.365 | rmse 2.71 | r2 -1.55 | sharp 0.00
epoch 23 | time used:  0.04s | train_loss 1.482 | valid loss 1.555 | valid acc 0.320 | mae 2.115 | mse 7.365 | rmse 2.71 | r2 -1.55 | sharp 0.00
epoch 24 | time used:  0.04s | train_loss 1.528 | valid loss 1.475 | valid acc 0.365 | mae 1.885 | mse 6.445 | rmse 2.54 | r2 -1.23 | sharp 1.02
epoch 25 | time used:  0.04s | train_loss 1.563 | valid loss 1.475 | valid acc 0.365 | mae 1.885 | mse 6.445 | rmse 2.54 | r2 -1.23 | sharp 1.02
epoch 26 | time used:  0.04s | train_loss 1.544 | valid loss 1.475 | valid acc 0.365 | mae 1.885 | mse 6.445 | rmse 2.54 | r2 -1.23 | sharp 1.02
epoch 27 | time used:  0.04s | train_loss 1.612 | valid loss 1.826 | valid acc 0.150 | mae 1.535 | mse 2.905 | rmse 1.70 | r2 -0.00 | sharp 1.02
epoch 28 | time used:  0.04s | train_loss 1.840 | valid loss 1.852 | valid acc 0.070 | mae 1.755 | mse 4.135 | rmse 2.03 | r2 -0.43 | sharp 1.02
epoch 29 | time used:  0.04s | train_loss 1.852 | valid loss 1.852 | valid acc 0.070 | mae 1.755 | mse 4.135 | rmse 2.03 | r2 -0.43 | sharp 1.02
epoch 30 | time used:  0.04s | train_loss 1.858 | valid loss 1.852 | valid acc 0.070 | mae 1.755 | mse 4.135 | rmse 2.03 | r2 -0.43 | sharp 1.02
saving the model to ./save/2022_50/CNN/checkpoint30.pt
epoch 31 | time used:  0.04s | train_loss 1.858 | valid loss 1.852 | valid acc 0.070 | mae 1.755 | mse 4.135 | rmse 2.03 | r2 -0.43 | sharp 1.02
epoch 32 | time used:  0.03s | train_loss 1.857 | valid loss 1.852 | valid acc 0.070 | mae 1.755 | mse 4.135 | rmse 2.03 | r2 -0.43 | sharp 1.02
epoch 33 | time used:  0.03s | train_loss 1.858 | valid loss 1.852 | valid acc 0.070 | mae 1.755 | mse 4.135 | rmse 2.03 | r2 -0.43 | sharp 1.02
epoch 34 | time used:  0.04s | train_loss 1.850 | valid loss 1.852 | valid acc 0.070 | mae 1.755 | mse 4.135 | rmse 2.03 | r2 -0.43 | sharp 1.02
epoch 35 | time used:  0.04s | train_loss 1.858 | valid loss 1.852 | valid acc 0.070 | mae 1.755 | mse 4.135 | rmse 2.03 | r2 -0.43 | sharp 1.02
epoch 36 | time used:  0.04s | train_loss 1.853 | valid loss 1.852 | valid acc 0.070 | mae 1.755 | mse 4.135 | rmse 2.03 | r2 -0.43 | sharp 1.02
epoch 37 | time used:  0.04s | train_loss 1.606 | valid loss 1.555 | valid acc 0.320 | mae 2.115 | mse 7.365 | rmse 2.71 | r2 -1.55 | sharp 0.00
epoch 38 | time used:  0.03s | train_loss 1.472 | valid loss 1.555 | valid acc 0.320 | mae 2.115 | mse 7.365 | rmse 2.71 | r2 -1.55 | sharp 0.00
epoch 39 | time used:  0.03s | train_loss 1.468 | valid loss 1.555 | valid acc 0.320 | mae 2.115 | mse 7.365 | rmse 2.71 | r2 -1.55 | sharp 0.00
epoch 40 | time used:  0.04s | train_loss 1.467 | valid loss 1.555 | valid acc 0.320 | mae 2.115 | mse 7.365 | rmse 2.71 | r2 -1.55 | sharp 0.00
saving the model to ./save/2022_50/CNN/checkpoint40.pt
epoch 41 | time used:  0.03s | train_loss 1.467 | valid loss 1.555 | valid acc 0.320 | mae 2.115 | mse 7.365 | rmse 2.71 | r2 -1.55 | sharp 0.00
epoch 42 | time used:  0.04s | train_loss 1.475 | valid loss 1.555 | valid acc 0.320 | mae 2.115 | mse 7.365 | rmse 2.71 | r2 -1.55 | sharp 0.00
epoch 43 | time used:  0.04s | train_loss 1.487 | valid loss 1.475 | valid acc 0.365 | mae 1.885 | mse 6.445 | rmse 2.54 | r2 -1.23 | sharp 1.02
epoch 44 | time used:  0.04s | train_loss 1.571 | valid loss 1.555 | valid acc 0.320 | mae 2.115 | mse 7.365 | rmse 2.71 | r2 -1.55 | sharp 0.00
epoch 45 | time used:  0.03s | train_loss 1.512 | valid loss 1.475 | valid acc 0.365 | mae 1.885 | mse 6.445 | rmse 2.54 | r2 -1.23 | sharp 1.02
